Workbook
Name Acc: Data!$K$1:$L$25
Name End_Date: Dashboard!$B$5
Name Start_Date: Dashboard!$B$4
Name Year_Slected: Dashboard!$N$2
Name Years: w!$G$6:$G$8

Sheet Read Me
A1: FINANCIAL STATEMENT DASHBOARD | PORTFOLIO PROJECT
A3: Purpose | B3: Demonstrate an Excel-based, formula-driven income statement, balance sheet, cash flow statement, trial balance, and automated reconciliation checks.
A4: Data status | B4: All transactions are simulated for portfolio demonstration; they are not actual company records.
A5: Coverage | B5: Monthly transaction activity from 1 January 2023 through 31 December 2025. Use the Dashboard year selector to view 2023, 2024, or 2025.
A6: Accounting basis | B6: Accrual-based income statement and balance sheet; direct-method cash flow statement. Journal entries use equal debits and credits.
A7: Revenue assumptions | B7: Sales, consulting, and service revenue are generated as simulated business activity. Receivables are recognized for credit sales/services and reduced when customers pay.
A8: Inventory / COGS assumption | B8: Inventory purchases are recorded as assets; cost of goods sold is recognized separately each month using a simulated percentage of merchandise sales. This is illustrative, not SKU-level inventory accounting.
A9: Cash flow policy | B9: Customer receipts and operating payments are operating activities; equipment purchases and dividend receipts are investing activities; owner contributions and bank-loan proceeds are financing activities. Interest paid is classified as operating.
A10: Retained earnings | B10: Retained earnings are calculated as cumulative income less cumulative expenses through the selected balance-sheet date; no dividends/distributions to owners are modeled.
A11: Limitations | B11: This is a synthetic portfolio case study, not audited financial information or tax/accounting advice. Real reporting would require source documents, inventory records, tax treatment, loan terms, and a documented accounting policy.
A12: Currency assumption | B12: USD is assumed for presentation, consistent with the source workbook’s dollar-formatted dashboard. All amounts are synthetic and illustrative.
A13: Workbook navigation
A14: Dashboard | B14: Year-selectable financial statements, cash flow, trial balance, and charts.
A15: Data | B15: Double-entry transaction ledger. Each Entry ID links two lines; Entry Difference should be zero.
A16: QA Checks | B16: Automated checks for journal balance, trial balance, balance sheet, cash flow tie-out, and monthly data coverage.

Sheet QA Checks
A1: AUTOMATED DATA & STATEMENT CHECKS
A3: Check | B3: Result | C3: Expected | D3: Purpose
A4: Journal entries balance | B4: =IF(COUNTIF(Data!$I$2:$I$1141,"<>0")=0,"PASS","CHECK") -> PASS | C4: PASS | D4: Each Entry ID has equal total debits and credits.
A5: Trial balance balances | B5: =IF(ABS(Dashboard!G135-Dashboard!H135)<0.01,"PASS","CHECK") -> PASS | C5: PASS | D5: Total debits equal total credits as of the selected year-end.
A6: Balance sheet balances | B6: =IF(ABS(Dashboard!F55-Dashboard!L55)<0.01,"PASS","CHECK") -> PASS | C6: PASS | D6: Total assets equal total liabilities and equity.
A7: Cash flow reconciles | B7: =IF(ABS(Dashboard!H103-Dashboard!F42)<0.01,"PASS","CHECK") -> PASS | C7: PASS | D7: Opening cash plus net cash flow equals closing cash and balance-sheet cash.
A8: Cash flow total formula | B8: =IF(ABS(Dashboard!H102-(Dashboard!H83+Dashboard!H92+Dashboard!H101))<0.01,"PASS","CHECK") -> PASS | C8: PASS | D8: Net period cash flow equals operating + investing + financing cash flows.
A9: Cash type only on cash rows | B9: =IF(SUMPRODUCT((Data!$E$2:$E$1141<>"")*(Data!$D$2:$D$1141<>"Cash"))=0,"PASS","CHECK") -> PASS | C9: PASS | D9: Cash flow categories are attached only to the Cash account line.
A12: Selected-year monthly coverage
A13: Month | B13: Transaction lines | C13: Status
A14: =DATE(Dashboard!$N$2,1,1) -> 45658 | B14: =COUNTIFS(Data!$A:$A,">="&A14,Data!$A:$A,"<"&EDATE(A14,1)) -> 32 | C14: =IF(B14>0,"PASS","MISSING") -> PASS
A15: =EDATE(A14,1) -> 45689 | B15: =COUNTIFS(Data!$A:$A,">="&A15,Data!$A:$A,"<"&EDATE(A15,1)) -> 30 | C15: =IF(B15>0,"PASS","MISSING") -> PASS
A16: =EDATE(A15,1) -> 45717 | B16: =COUNTIFS(Data!$A:$A,">="&A16,Data!$A:$A,"<"&EDATE(A16,1)) -> 36 | C16: =IF(B16>0,"PASS","MISSING") -> PASS
A17: =EDATE(A16,1) -> 45748 | B17: =COUNTIFS(Data!$A:$A,">="&A17,Data!$A:$A,"<"&EDATE(A17,1)) -> 30 | C17: =IF(B17>0,"PASS","MISSING") -> PASS
A18: =EDATE(A17,1) -> 45778 | B18: =COUNTIFS(Data!$A:$A,">="&A18,Data!$A:$A,"<"&EDATE(A18,1)) -> 30 | C18: =IF(B18>0,"PASS","MISSING") -> PASS
A19: =EDATE(A18,1) -> 45809 | B19: =COUNTIFS(Data!$A:$A,">="&A19,Data!$A:$A,"<"&EDATE(A19,1)) -> 34 | C19: =IF(B19>0,"PASS","MISSING") -> PASS
A20: =EDATE(A19,1) -> 45839 | B20: =COUNTIFS(Data!$A:$A,">="&A20,Data!$A:$A,"<"&EDATE(A20,1)) -> 30 | C20: =IF(B20>0,"PASS","MISSING") -> PASS
A21: =EDATE(A20,1) -> 45870 | B21: =COUNTIFS(Data!$A:$A,">="&A21,Data!$A:$A,"<"&EDATE(A21,1)) -> 30 | C21: =IF(B21>0,"PASS","MISSING") -> PASS
A22: =EDATE(A21,1) -> 45901 | B22: =COUNTIFS(Data!$A:$A,">="&A22,Data!$A:$A,"<"&EDATE(A22,1)) -> 34 | C22: =IF(B22>0,"PASS","MISSING") -> PASS
A23: =EDATE(A22,1) -> 45931 | B23: =COUNTIFS(Data!$A:$A,">="&A23,Data!$A:$A,"<"&EDATE(A23,1)) -> 30 | C23: =IF(B23>0,"PASS","MISSING") -> PASS
A24: =EDATE(A23,1) -> 45962 | B24: =COUNTIFS(Data!$A:$A,">="&A24,Data!$A:$A,"<"&EDATE(A24,1)) -> 30 | C24: =IF(B24>0,"PASS","MISSING") -> PASS
A25: =EDATE(A24,1) -> 45992 | B25: =COUNTIFS(Data!$A:$A,">="&A25,Data!$A:$A,"<"&EDATE(A25,1)) -> 34 | C25: =IF(B25>0,"PASS","MISSING") -> PASS
A27: Full selected-year coverage | B27: =IF(COUNTIF(C14:C25,"MISSING")=0,"PASS","CHECK") -> PASS | C27: PASS | D27: All 12 months must contain transaction lines for the selected year.
A29: Selected year | B29: =Dashboard!N2 -> 2025
A30: Transaction line count | B30: =COUNTIFS(Data!$A:$A,">="&DATE(Dashboard!$N$2,1,1),Data!$A:$A,"<"&DATE(Dashboard!$N$2+1,1,1)) -> 380
A31: Journal entry count | B31: =COUNTIFS(Data!$A:$A,">="&DATE(Dashboard!$N$2,1,1),Data!$A:$A,"<"&DATE(Dashboard!$N$2+1,1,1))/2 -> 190

Sheet Dashboard
E1: FINANCIAL STATEMENT ANALYSIS
M2: Select year | N2: 2025
A4: Start Date | B4: =DATE(Year_Slected,1,1) -> 45658
A5: End Date | B5: =DATE(Year_Slected,12,31) -> 46022
C7: PROFIT & LOSS
C8: ="FROM "&TEXT(Start_Date,"dd-mm-yyyy") & " To " & TEXT(End_Date, "dd-mm-yyyy") -> FROM 01-01-2025 To 31-12-2025
D9: P & L
D10: Income
E11: Consulting Revenue | H11: =SUMIFS(Data!$G:$G,Data!$D:$D,E11,Data!$A:$A,">="&Start_Date,Data!$A:$A,"<="&End_Date)-SUMIFS(Data!$F:$F,Data!$D:$D,E11,Data!$A:$A,">="&Start_Date,Data!$A:$A,"<="&End_Date) -> 73000
E12: Dividend Income | H12: =SUMIFS(Data!$G:$G,Data!$D:$D,E12,Data!$A:$A,">="&Start_Date,Data!$A:$A,"<="&End_Date)-SUMIFS(Data!$F:$F,Data!$D:$D,E12,Data!$A:$A,">="&Start_Date,Data!$A:$A,"<="&End_Date) -> 7000
E13: Sales Revenue | H13: =SUMIFS(Data!$G:$G,Data!$D:$D,E13,Data!$A:$A,">="&Start_Date,Data!$A:$A,"<="&End_Date)-SUMIFS(Data!$F:$F,Data!$D:$D,E13,Data!$A:$A,">="&Start_Date,Data!$A:$A,"<="&End_Date) -> 485000
E14: Service Revenue | H14: =SUMIFS(Data!$G:$G,Data!$D:$D,E14,Data!$A:$A,">="&Start_Date,Data!$A:$A,"<="&End_Date)-SUMIFS(Data!$F:$F,Data!$D:$D,E14,Data!$A:$A,">="&Start_Date,Data!$A:$A,"<="&End_Date) -> 110000
D15: Total Income | H15: =SUM(H11:H14) -> 675000
D16: COGS
E17: Cost of Goods Sold | H17: =SUMIFS(Data!$F:$F,Data!$D:$D,E17,Data!$A:$A,">="&Start_Date,Data!$A:$A,"<="&End_Date)-SUMIFS(Data!$G:$G,Data!$D:$D,E17,Data!$A:$A,">="&Start_Date,Data!$A:$A,"<="&End_Date) -> 208500
H18: =0 -> 0
D19: Total COGS | H19: =H17 -> 208500
D20: Gross Profit | I20: =H15-H19 -> 466500
D21: Expenses
E22: Advertising Expense | H22: =SUMIFS(Data!$F:$F,Data!$D:$D,E22,Data!$A:$A,">="&Start_Date,Data!$A:$A,"<="&End_Date)-SUMIFS(Data!$G:$G,Data!$D:$D,E22,Data!$A:$A,">="&Start_Date,Data!$A:$A,"<="&End_Date) -> 14500
E23: Salaries Expense | H23: =SUMIFS(Data!$F:$F,Data!$D:$D,E23,Data!$A:$A,">="&Start_Date,Data!$A:$A,"<="&End_Date)-SUMIFS(Data!$G:$G,Data!$D:$D,E23,Data!$A:$A,">="&Start_Date,Data!$A:$A,"<="&End_Date) -> 72500
E24: Depreciation Expense | H24: =SUMIFS(Data!$F:$F,Data!$D:$D,E24,Data!$A:$A,">="&Start_Date,Data!$A:$A,"<="&End_Date)-SUMIFS(Data!$G:$G,Data!$D:$D,E24,Data!$A:$A,">="&Start_Date,Data!$A:$A,"<="&End_Date) -> 11200
E25: Insurance Expense | H25: =SUMIFS(Data!$F:$F,Data!$D:$D,E25,Data!$A:$A,">="&Start_Date,Data!$A:$A,"<="&End_Date)-SUMIFS(Data!$G:$G,Data!$D:$D,E25,Data!$A:$A,">="&Start_Date,Data!$A:$A,"<="&End_Date) -> 6000
E26: Interest Expense | H26: =SUMIFS(Data!$F:$F,Data!$D:$D,E26,Data!$A:$A,">="&Start_Date,Data!$A:$A,"<="&End_Date)-SUMIFS(Data!$G:$G,Data!$D:$D,E26,Data!$A:$A,">="&Start_Date,Data!$A:$A,"<="&End_Date) -> 9500
E27: Office Supplies Expense | H27: =SUMIFS(Data!$F:$F,Data!$D:$D,E27,Data!$A:$A,">="&Start_Date,Data!$A:$A,"<="&End_Date)-SUMIFS(Data!$G:$G,Data!$D:$D,E27,Data!$A:$A,">="&Start_Date,Data!$A:$A,"<="&End_Date) -> 1700
E28: Rent Expense | H28: =SUMIFS(Data!$F:$F,Data!$D:$D,E28,Data!$A:$A,">="&Start_Date,Data!$A:$A,"<="&End_Date)-SUMIFS(Data!$G:$G,Data!$D:$D,E28,Data!$A:$A,">="&Start_Date,Data!$A:$A,"<="&End_Date) -> 63500
E29: Repairs Expense | H29: =SUMIFS(Data!$F:$F,Data!$D:$D,E29,Data!$A:$A,">="&Start_Date,Data!$A:$A,"<="&End_Date)-SUMIFS(Data!$G:$G,Data!$D:$D,E29,Data!$A:$A,">="&Start_Date,Data!$A:$A,"<="&End_Date) -> 1500
E30: Tax Expense | H30: =SUMIFS(Data!$F:$F,Data!$D:$D,E30,Data!$A:$A,">="&Start_Date,Data!$A:$A,"<="&End_Date)-SUMIFS(Data!$G:$G,Data!$D:$D,E30,Data!$A:$A,">="&Start_Date,Data!$A:$A,"<="&End_Date) -> 3000
E31: Travel Expense | H31: =SUMIFS(Data!$F:$F,Data!$D:$D,E31,Data!$A:$A,">="&Start_Date,Data!$A:$A,"<="&End_Date)-SUMIFS(Data!$G:$G,Data!$D:$D,E31,Data!$A:$A,">="&Start_Date,Data!$A:$A,"<="&End_Date) -> 1000
E32: Utilities Expense | H32: =SUMIFS(Data!$F:$F,Data!$D:$D,E32,Data!$A:$A,">="&Start_Date,Data!$A:$A,"<="&End_Date)-SUMIFS(Data!$G:$G,Data!$D:$D,E32,Data!$A:$A,">="&Start_Date,Data!$A:$A,"<="&End_Date) -> 24000
D33: Total Expenses | H33: =SUM(H22:H32) -> 208400
D34: Net Profit | I34: =I20-H33 -> 258100
C38: BALANCE SHEET
C39: ="As At "&TEXT(End_Date, "dd-mm-yyyy") -> As At 31-12-2025
D40: Balance Sheet
D41: Current Asset | J41: Current Liability
E42: Cash | F42: =SUMIFS(Data!$F:$F,Data!$D:$D,E42,Data!$A:$A,"<="&End_Date)-SUMIFS(Data!$G:$G,Data!$D:$D,E42,Data!$A:$A,"<="&End_Date) -> 1119400 | K42: Accounts Payable | L42: =SUMIFS(Data!$G:$G,Data!$D:$D,K42,Data!$A:$A,"<="&End_Date)-SUMIFS(Data!$F:$F,Data!$D:$D,K42,Data!$A:$A,"<="&End_Date) -> 707000
E43: Accounts Receivable | F43: =SUMIFS(Data!$F:$F,Data!$D:$D,E43,Data!$A:$A,"<="&End_Date)-SUMIFS(Data!$G:$G,Data!$D:$D,E43,Data!$A:$A,"<="&End_Date) -> 326000 | K43: Unearned Revenue | L43: =SUMIFS(Data!$G:$G,Data!$D:$D,K43,Data!$A:$A,"<="&End_Date)-SUMIFS(Data!$F:$F,Data!$D:$D,K43,Data!$A:$A,"<="&End_Date) -> 0
E44: Inventory | F44: =SUMIFS(Data!$F:$F,Data!$D:$D,E44,Data!$A:$A,"<="&End_Date)-SUMIFS(Data!$G:$G,Data!$D:$D,E44,Data!$A:$A,"<="&End_Date) -> 125000 | J44: Total Current Liabilities | L44: =SUM(L42:L43) -> 707000
D45: Total Current Assets | F45: =SUM(F42:F44) -> 1570400
...

Sheet w
D4: Accounts & Types
D5: Name | E5: Type | G5: Years
D6: Cash | E6: Asset | G6: 2023
D7: Common Stock | E7: Equity | G7: 2024
D8: Equipment | E8: Asset | G8: 2025
D9: Accounts Receivable | E9: Asset
D10: Sales Revenue | E10: Income
D11: Rent Expense | E11: COGS
D12: Bank Loan | E12: Liability
D13: Inventory | E13: Asset
D14: Accounts Payable | E14: Liability
D15: Salaries Expense | E15: COGS
D16: Depreciation Expense | E16: Expense
D17: Accumulated Depr. | E17: Asset
D18: Consulting Revenue | E18: Income
D19: Utilities Expense | E19: Expense
D20: Prepaid Rent | E20: Asset
... D32: Materials Purchased | E32: COGS

Sheet Data
A1: Date | B1: Description | C1: Acct. Type | D1: Account Name | E1: Cash Type | F1: Debits | G1: Credits | H1: Entry ID | I1: Entry Difference | K1: Account Name | L1: Account Type | O1: P & L | S1: Balance Sheet | Y1: CASH FLOWS | AD1: Trial balance
A2: 44927 | B2: Owner capital contribution | C2: Asset | D2: Cash | E2: Financing Income | F2: 50000 | H2: JE0001 | I2: =SUMIF($H:$H,H2,$F:$F)-SUMIF($H:$H,H2,$G:$G) -> 0 | K2: Cash | L2: Asset | O2: Income | S2: Current Asset | V2: Current Liability | Y2: Previous Net Earnings | AD2: Account Name | AF2: Account Type
A3: 44927 | B3: Owner capital contribution | C3: Equity | D3: Common Stock | G3: 50000 | H3: JE0001 | I3: =SUMIF($H:$H,H3,$F:$F)-SUMIF($H:$H,H3,$G:$G) -> 0 | K3: Accounts Receivable | L3: Asset | P3: Consulting Revenue | T3: Prepaid Rent | W3: Accounts Payable | Y3: Cash Flow From Operating Activities | AD3: Cash | AF3: Asset
A4: 44928 | B4: Sold goods on account | C4: Asset | D4: Accounts Receivable | F4: 20000 | H4: JE0002 | I4: =SUMIF($H:$H,H4,$F:$F)-SUMIF($H:$H,H4,$G:$G) -> 0 | K4: Inventory | L4: Asset | P4: Dividend Income | T4: Cash | W4: Unearned Revenue | Z4: Cash receipts from | AD4: Common Stock | AF4: Asset
A5: 44928 | B5: Sold goods on account | C5: Income | D5: Sales Revenue | G5: 20000 | H5: JE0002 | I5: =SUMIF($H:$H,H5,$F:$F)-SUMIF($H:$H,H5,$G:$G) -> 0 | K5: Equipment | L5: Asset | P5: Sales Revenue | T5: Inventory | V5: Total Current Liability | AA5: Provided consulting services | AD5: Equipment | AF5: Asset
A6: 44929 | B6: Purchased inventory | C6: Asset | D6: Inventory | F6: 16500 | H6: JE0003 | I6: =SUMIF($H:$H,H6,$F:$F)-SUMIF($H:$H,H6,$G:$G) -> 0 | K6: Accumulated Depreciation | L6: Asset | P6: Service Revenue | S6: Total Current Asset | AA6: Received payment on account | AD6: Accounts Receivable | AF6: Asset
A7: 44929 | B7: Purchased inventory | C7: Liability | D7: Accounts Payable | G7: 16500 | H7: JE0003 | I7: =SUMIF($H:$H,H7,$F:$F)-SUMIF($H:$H,H7,$G:$G) -> 0 | K7: Accounts Payable | L7: Liability | O7: Total Income | V7: Long Term Liability | AA7: Sold goods for cash | AD7: Inventory | AF7: Asset
A8: 44930 | B8: Paid supplier | C8: Liability | D8: Accounts Payable | F8: 0 | H8: JE0004 | I8: =SUMIF($H:$H,H8,$F:$F)-SUMIF($H:$H,H8,$G:$G) -> 0 | K8: Bank Loan | L8: Liability | O8: COGS | S8: Fixed Assets | W8: Bank Loan | Z8: Total Operating Cash Inflows | AD8: Accumulated Depr. | AF8: Asset
A9: 44930 | B9: Paid supplier | C9: Asset | D9: Cash | E9: Operating Expense | G9: 0 | H9: JE0004 | I9: =SUMIF($H:$H,H9,$F:$F)-SUMIF($H:$H,H9,$G:$G) -> 0 | K9: Common Stock | L9: Equity | P9: Materials Purchased | T9: Equipment | V9: Total Long Term Liability | Z9: Cash paid for | AD9: Prepaid Rent | AF9: Asset
A10: 44931 | B10: Sold goods for cash | C10: Asset | D10: Cash | E10: Operating Income | F10: 16000 | H10: JE0005 | I10: =SUMIF($H:$H,H10,$F:$F)-SUMIF($H:$H,H10,$G:$G) -> 0 | K10: Sales Revenue | L10: Income | P10: Salaries Expense | T10: Accumulated Depr. | AA10: Paid Rent | AD10: Rent Expense | AF10: COGS
A11: 44931 | B11: Sold goods for cash | C11: Income | D11: Sales Revenue | G11: 16000 | H11: JE0005 | I11: =SUMIF($H:$H,H11,$F:$F)-SUMIF($H:$H,H11,$G:$G) -> 0 | K11: Consulting Revenue | L11: Income | O11: Total COGS | S11: Total Fixed Assetes | V11: Equiity | AA11: Paid salaries | AD11: Salaries Expense | AF11: COGS
A12: 44932 | B12: Provided consulting services | C12: Asset | D12: Cash | E12: Operating Income | F12: 6000 | H12: JE0006 | I12: =SUMIF($H:$H,H12,$F:$F)-SUMIF($H:$H,H12,$G:$G) -> 0 | K12: Service Revenue | L12: Income | O12: Gross Profit | W12: Common Stock | AA12: Paid utilities | AD12: Materials Purchased | AF12: COGS
A13: 44932 | B13: Provided consulting services | C13: Income | D13: Consulting Revenue | G13: 6000 | H13: JE0006 | I13: =SUMIF($H:$H,H13,$F:$F)-SUMIF($H:$H,H13,$G:$G) -> 0 | K13: Dividend Income | L13: Income | O13: Expenses | W13: Retained Earnings | AA13: Paid advertising | AD13: Depreciation Expense | AF13: Expense
A14: 44933 | B14: Provided services on account | C14: Asset | D14: Accounts Receivable | F14: 9000 | H14: JE0007 | I14: =SUMIF($H:$H,H14,$F:$F)-SUMIF($H:$H,H14,$G:$G) -> 0 | K14: Cost of Goods Sold | L14: Expense | P14: Advertising Expense | V14: Total Equity | AA14: Paid supplier | AD14: Utilities Expense | AF14: Expense
A15: 44933 | B15: Provided services on account | C15: Income | D15: Service Revenue | G15: 9000 | H15: JE0007 | I15: =SUMIF($H:$H,H15,$F:$F)-SUMIF($H:$H,H15,$G:$G) -> 0 | K15: Salaries Expense | L15: Expense | P15: Bad Debt Expense | AA15: Purchased Materials | AD15: Advertising Expense | AF15: Expense
A16: 44934 | B16: Received payment on account | C16: Asset | D16: Cash | E16: Operating Income | F16: 19000 | H16: JE0008 | I16: =SUMIF($H:$H,H16,$F:$F)-SUMIF($H:$H,H16,$G:$G) -> 0 | K16: Rent Expense | L16: Expense | P16: Depreciation Expense | AA16: Paid travel expenses | AD16: Travel Expense | AF16: Expense
A17: 44934 | B17: Received payment on account | C17: Asset | D17: Accounts Receivable | G17: 19000 | H17: JE0008 | I17: =SUMIF($H:$H,H17,$F:$F)-SUMIF($H:$H,H17,$G:$G) -> 0 | K17: Utilities Expense | L17: Expense | P17: Insurance Expense | AA17: Paid insurance | AD17: Insurance Expense | AF17: Expense
A18: 44935 | B18: Paid Rent | C18: Expense | D18: Rent Expense | F18: 4500 | H18: JE0009 | I18: =SUMIF($H:$H,H18,$F:$F)-SUMIF($H:$H,H18,$G:$G) -> 0 | K18: Advertising Expense | L18: Expense | P18: Interest Expense | AA18: Paid office supplies | AD18: Tax Expense | AF18: Expense
A19: 44935 | B19: Paid Rent | C19: Asset | D19: Cash | E19: Operating Expense | G19: 4500 | H19: JE0009 | I19: =SUMIF($H:$H,H19,$F:$F)-SUMIF($H:$H,H19,$G:$G) -> 0 | K19: Travel Expense | L19: Expense | P19: Office Supplies | AA19: Paid taxes | AD19: Bad Debt Expense | AF19: Expense
A20: 44936 | B20: Paid salaries | C20: Expense | D20: Salaries Expense | F20: 7000 | H20: JE0010 | I20: =SUMIF($H:$H,H20,$F:$F)-SUMIF($H:$H,H20,$G:$G) -> 0 | K20: Insurance Expense | L20: Expense | P20: Rent Expense | AA20: Paid repairs | AD20: Repairs Expense | AF20: Expense
A21: 44936 | B21: Paid salaries | C21: Asset | D21: Cash | E21: Operating Expense | G21: 7000 | H21: JE0010 | I21: =SUMIF($H:$H,H21,$F:$F)-SUMIF($H:$H,H21,$G:$G) -> 0 | K21: Office Supplies Expense | L21: Expense | P21: Repairs Expense | Z21: Total Operating Cash Outflows | AD21: Sales Revenue | AF21: Income
A22: 44937 | B22: Paid utilities | C22: Expense | D22: Utilities Expense | F22: 2000 | H22: JE0011 | I22: =SUMIF($H:$H,H22,$F:$F)-SUMIF($H:$H,H22,$G:$G) -> 0 | K22: Tax Expense | L22: Expense | P22: Tax Expense | Y22: Net Cash Flow from Operations | AD22: Consulting Revenue | AF22: Income
A23: 44937 | B23: Paid utilities | C23: Asset | D23: Cash | E23: Operating Expense | G23: 2000 | H23: JE0011 | I23: =SUMIF($H:$H,H23,$F:$F)-SUMIF($H:$H,H23,$G:$G) -> 0 | K23: Repairs Expense | L23: Expense | P23: Travel Expense | AD23: Office Supplies | AF23: Income
A24: 44938 | B24: Paid advertising | C24: Expense | D24: Advertising Expense | F24: 1500 | H24: JE0012 | I24: =SUMIF($H:$H,H24,$F:$F)-SUMIF($H:$H,H24,$G:$G) -> 0 | K24: Interest Expense | L24: Expense | P24: Utilities Expense | Y24: Cash Flow From Investing Activities | AD24: Interest Expense | AF24: Income
A25: 44938 | B25: Paid advertising | C25: Asset | D25: Cash | E25: Operating Expense | G25: 1500 | H25: JE0012 | I25: =SUMIF($H:$H,H25,$F:$F)-SUMIF($H:$H,H25,$G:$G) -> 0 | K25: Depreciation Expense | L25: Expense | O25: Total Expenses | Z25: Cash receipts from Investing | AD25: Service Revenue | AF25: Income
A26: 44939 | B26: Paid repairs | C26: Expense | D26: Repairs Expense | F26: 1000 | H26: JE0013 | I26: =SUMIF($H:$H,H26,$F:$F)-SUMIF($H:$H,H26,$G:$G) -> 0 | O26: Net Profit | AA26: Received dividend income | AD26: Dividend Income | AF26: Income
A27: 44939 | B27: Paid repairs | C27: Asset | D27: Cash | E27: Operating Expense | G27: 1000 | H27: JE0013 | I27: =SUMIF($H:$H,H27,$F:$F)-SUMIF($H:$H,H27,$G:$G) -> 0 | Z27: Total cash receipts from Investing | AD27: Bank Loan | AF27: Liability
A28: 44940 | B28: Paid interest on loan | C28: Expense | D28: Interest Expense | F28: 1500 | H28: JE0014 | I28: =SUMIF($H:$H,H28,$F:$F)-SUMIF($H:$H,H28,$G:$G) -> 0 | Z28: Cash paid for investing | AD28: Accounts Payable | AF28: Liability
A29: 44940 | B29: Paid interest on loan | C29: Asset | D29: Cash | E29: Operating Expense | G29: 1500 | H29: JE0014 | I29: =SUMIF($H:$H,H29,$F:$F)-SUMIF($H:$H,H29,$G:$G) -> 0 | AA29: Purchased equipment | AD29: Unearned Revenue | AF29: Liability
A30: 44952 | B30: Recognized cost of goods sold | C30: Expense | D30: Cost of Goods Sold | F30: 14500 | H30: JE0015 | I30: =SUMIF($H:$H,H30,$F:$F)-SUMIF($H:$H,H30,$G:$G) -> 0 | Z30: Total cash paid for investing
A31: 44952 | B31: Recognized cost of goods sold | C31: Asset | D31: Inventory | G31: 14500 | H31: JE0015 | I31: =SUMIF($H:$H,H31,$F:$F)-SUMIF($H:$H,H31,$G:$G) -> 0 | Y31: Net cash Flow From Investing
A32: 44953 | B32: Recorded depreciation | C32: Expense | D32: Depreciation Expense | F32: 700 | H32: JE0016 | I32: =SUMIF($H:$H,H32,$F:$F)-SUMIF($H:$H,H32,$G:$G) -> 0 | Z32: Cash paid for investing
A33: 44953 | B33: Recorded depreciation | C33: Asset | D33: Accumulated Depreciation | G33: 700 | H33: JE0016 | I33: =SUMIF($H:$H,H33,$F:$F)-SUMIF($H:$H,H33,$G:$G) -> 0 | Y33: Financing Activities
A34: 44959 | B34: Sold goods on account | C34: Asset | D34: Accounts Receivable | F34: 20000 | H34: JE0017 | I34: =SUMIF($H:$H,H34,$F:$F)-SUMIF($H:$H,H34,$G:$G) -> 0 | Z34: Cash receipts from
A35: 44959 | B35: Sold goods on account | C35: Income | D35: Sales Revenue | G35: 20000 | H35: JE0017 | I35: =SUMIF($H:$H,H35,$F:$F)-SUMIF($H:$H,H35,$G:$G) -> 0 | AA35: Received loan from bank
A36: 44960 | B36: Purchased inventory | C36: Asset | D36: Inventory | F36: 18000 | H36: JE0018 | I36: =SUMIF($H:$H,H36,$F:$F)-SUMIF($H:$H,H36,$G:$G) -> 0 | Z36: Total casceipts from Financing
A37: 44960 | B37: Purchased inventory | C37: Liability | D37: Accounts Payable | G37: 18000 | H37: JE0018 | I37: =SUMIF($H:$H,H37,$F:$F)-SUMIF($H:$H,H37,$G:$G) -> 0 | Z37: Cash paid for financing
A38: 44961 | B38: Paid supplier | C38: Liability | D38: Accounts Payable | F38: 0 | H38: JE0019 | I38: =SUMIF($H:$H,H38,$F:$F)-SUMIF($H:$H,H38,$G:$G) -> 0 | AA38: Initial cash investment
A39: 44961 | B39: Paid supplier | C39: Asset | D39: Cash | E39: Operating Expense | G39: 0 | H39: JE0019 | I39: =SUMIF($H:$H,H39,$F:$F)-SUMIF($H:$H,H39,$G:$G) -> 0 | Z39: Net Cash Flow (Financing Activities) | AA39: Paid interest on loan
A40: 44962 | B40: Sold goods for cash | C40: Asset | D40: Cash | E40: Operating Income | F40: 18000 | H40: JE0020 | I40: =SUMIF($H:$H,H40,$F:$F)-SUMIF($H:$H,H40,$G:$G) -> 0 | Y40: Net cash flow from financing
...
